<?xml version="1.0" encoding="utf-8"?>

<!-- =================================================================================== -->
<!-- |    This document was autogenerated by xacro from panda_arm_hand.urdf.xacro      | -->
<!-- |    EDITING THIS FILE BY HAND IS NOT RECOMMENDED                                 | -->
<!-- =================================================================================== -->
<robot name="panda2" xmlns:xacro="http://www.ros.org/wiki/xacro">
  <link name="world" />
  <link name="panda2_link0">
    <inertial>
      <origin rpy="0 0 0" xyz="0 0 0.05" />
      <mass value="2.9" />
      <inertia ixx="0.1" ixy="0" ixz="0" iyy="0.1" iyz="0" izz="0.1" />
    </inertial>
    <visual>
      <geometry>
        <mesh filename="package://description/meshes/collision/link0.obj" />
      </geometry>
      <material name="panda_white">
        <color rgba="1. 1. 1. 1." />
      </material>
    </visual>
    <collision>
      <geometry>
        <mesh filename="package://description/meshes/collision/link0.obj" />
      </geometry>
      <material name="panda_white" />
    </collision>
  </link>
  <joint name="panda2_joint_world" type="fixed">
    <origin xyz="0 0 0" rpy="0 0 0" />
    <parent link="world" />
    <child link="panda2_link0" />
  </joint>
  <link name="panda2_link1">
    <inertial>
      <origin rpy="0 0 0" xyz="0 -0.04 -0.05" />
      <mass value="2.7" />
      <inertia ixx="0.1" ixy="0" ixz="0" iyy="0.1" iyz="0" izz="0.1" />
    </inertial>
    <visual>
      <geometry>
        <mesh filename="package://description/meshes/visual/link1.obj" />
      </geometry>
      <material name="panda_white" />
    </visual>
    <collision>
      <geometry>
        <mesh filename="package://description/meshes/collision/link1.obj" />
      </geometry>
      <material name="panda_white" />
    </collision>
  </link>
  <joint name="panda2_joint1" type="revolute">
    <safety_controller k_position="100.0" k_velocity="40.0" soft_lower_limit="-2.8973"
      soft_upper_limit="2.8973" />
    <origin rpy="0 0 0" xyz="0 0 0.333" />
    <parent link="panda2_link0" />
    <child link="panda2_link1" />
    <axis xyz="0 0 1" />
    <limit effort="87" lower="-2.9671" upper="2.9671" velocity="2.1750" />
  </joint>
  <link name="panda2_link2">
    <inertial>
      <origin rpy="0 0 0" xyz="0 -0.04 0.06" />
      <mass value="2.73" />
      <inertia ixx="0.1" ixy="0" ixz="0" iyy="0.1" iyz="0" izz="0.1" />
    </inertial>
    <visual>
      <geometry>
        <mesh filename="package://description/meshes/visual/link2.obj" />
      </geometry>
      <material name="panda_white" />
    </visual>
    <collision>
      <geometry>
        <mesh filename="package://description/meshes/collision/link2.obj" />
      </geometry>
      <material name="panda_white" />
    </collision>
  </link>
  <joint name="panda2_joint2" type="revolute">
    <safety_controller k_position="100.0" k_velocity="40.0" soft_lower_limit="-1.7628"
      soft_upper_limit="1.7628" />
    <origin rpy="-1.57079632679 0 0" xyz="0 0 0" />
    <parent link="panda2_link1" />
    <child link="panda2_link2" />
    <axis xyz="0 0 1" />
    <limit effort="87" lower="-1.8326" upper="1.8326" velocity="2.1750" />
  </joint>
  <link name="panda2_link3">
    <inertial>
      <origin rpy="0 0 0" xyz="0.01 0.01 -0.05" />
      <mass value="2.04" />
      <inertia ixx="0.1" ixy="0" ixz="0" iyy="0.1" iyz="0" izz="0.1" />
    </inertial>
    <visual>
      <geometry>
        <mesh filename="package://description/meshes/visual/link3.obj" />
      </geometry>
      <material name="panda_red">
        <color rgba="1. 1. 1. 1." />
      </material>
    </visual>
    <collision>
      <geometry>
        <mesh filename="package://description/meshes/collision/link3.obj" />
      </geometry>
    </collision>
  </link>
  <joint name="panda2_joint3" type="revolute">
    <safety_controller k_position="100.0" k_velocity="40.0" soft_lower_limit="-2.8973"
      soft_upper_limit="2.8973" />
    <origin rpy="1.57079632679 0 0" xyz="0 -0.316 0" />
    <parent link="panda2_link2" />
    <child link="panda2_link3" />
    <axis xyz="0 0 1" />
    <limit effort="87" lower="-2.9671" upper="2.9671" velocity="2.1750" />
  </joint>
  <link name="panda2_link4">
    <inertial>
      <origin rpy="0 0 0" xyz="-0.03 0.03 0.02" />
      <mass value="2.08" />
      <inertia ixx="0.1" ixy="0" ixz="0" iyy="0.1" iyz="0" izz="0.1" />
    </inertial>
    <visual>
      <geometry>
        <mesh filename="package://description/meshes/visual/link4.obj" />
      </geometry>
      <material name="panda_white" />
    </visual>
    <collision>
      <geometry>
        <mesh filename="package://description/meshes/collision/link4.obj" />
      </geometry>
      <material name="panda_white" />
    </collision>
  </link>
  <joint name="panda2_joint4" type="revolute">
    <safety_controller k_position="100.0" k_velocity="40.0" soft_lower_limit="-3.0718"
      soft_upper_limit="-0.0698" />
    <origin rpy="1.57079632679 0 0" xyz="0.0825 0 0" />
    <parent link="panda2_link3" />
    <child link="panda2_link4" />
    <axis xyz="0 0 1" />
    <limit effort="87" lower="-3.1416" upper="0.0" velocity="2.1750" />
  </joint>
  <link name="panda2_link5">
    <inertial>
      <origin rpy="0 0 0" xyz="0 0.04 -0.12" />
      <mass value="3" />
      <inertia ixx="0.1" ixy="0" ixz="0" iyy="0.1" iyz="0" izz="0.1" />
    </inertial>
    <visual>
      <geometry>
        <mesh filename="package://description/meshes/visual/link5.obj" />
      </geometry>
      <material name="panda_white" />
    </visual>
    <collision>
      <geometry>
        <mesh filename="package://description/meshes/collision/link5.obj" />
      </geometry>
      <material name="panda_white" />
    </collision>
  </link>
  <joint name="panda2_joint5" type="revolute">
    <safety_controller k_position="100.0" k_velocity="40.0" soft_lower_limit="-2.8973"
      soft_upper_limit="2.8973" />
    <origin rpy="-1.57079632679 0 0" xyz="-0.0825 0.384 0" />
    <parent link="panda2_link4" />
    <child link="panda2_link5" />
    <axis xyz="0 0 1" />
    <limit effort="12" lower="-2.9671" upper="2.9671" velocity="2.6100" />
  </joint>
  <link name="panda2_link6">
    <inertial>
      <origin rpy="0 0 0" xyz="0.04 0 0" />
      <mass value="1.3" />
      <inertia ixx="0.1" ixy="0" ixz="0" iyy="0.1" iyz="0" izz="0.1" />
    </inertial>
    <visual>
      <geometry>
        <mesh filename="package://description/meshes/visual/link6.obj" />
      </geometry>
      <material name="panda_white" />
    </visual>
    <collision>
      <geometry>
        <mesh filename="package://description/meshes/collision/link6.obj" />
      </geometry>
      <material name="panda_white" />
    </collision>
  </link>
  <joint name="panda2_joint6" type="revolute">
    <safety_controller k_position="100.0" k_velocity="40.0" soft_lower_limit="-0.0175"
      soft_upper_limit="3.7525" />
    <origin rpy="-1.57079632679 0 0" xyz="0 0 0" />
    <parent link="panda2_link5" />
    <child link="panda2_link6" />
    <axis xyz="0 0 1" />
    <limit effort="12" lower="-0.0873" upper="3.8223" velocity="2.6100" />
  </joint>
  <link name="panda2_link7">
    <inertial>
      <origin rpy="0 0 0" xyz="0 0 0.08" />
      <mass value=".2" />
      <inertia ixx="0.1" ixy="0" ixz="0" iyy="0.1" iyz="0" izz="0.1" />
    </inertial>
    <visual>
      <geometry>
        <mesh filename="package://description/meshes/collision/link7.obj" />
      </geometry>
      <material name="panda_white" />
    </visual>
    <collision>
      <geometry>
        <mesh filename="package://description/meshes/collision/link7.obj" />
      </geometry>
      <material name="panda_white" />
    </collision>
  </link>
  <joint name="panda2_joint7" type="revolute">
    <safety_controller k_position="100.0" k_velocity="40.0" soft_lower_limit="-2.8973"
      soft_upper_limit="2.8973" />
    <origin rpy="1.57079632679 0 0" xyz="0.088 0 0" />
    <parent link="panda2_link6" />
    <child link="panda2_link7" />
    <axis xyz="0 0 1" />
    <limit effort="12" lower="-2.9671" upper="2.9671" velocity="2.6100" />
  </joint>
  <link name="panda2_link8">
    <inertial>
      <origin rpy="0 0 0" xyz="0 0 0" />
      <mass value="0.0" />
      <inertia ixx="0.1" ixy="0" ixz="0" iyy="0.1" iyz="0" izz="0.1" />
    </inertial>
  </link>
  <joint name="panda2_joint8" type="fixed">
    <origin rpy="0 0 0" xyz="0 0 0.107" />
    <parent link="panda2_link7" />
    <child link="panda2_link8" />
    <axis xyz="0 0 0" />
  </joint>
  <joint name="panda2_hand_joint" type="fixed">
    <parent link="panda2_link8" />
    <child link="panda2_hand" />
    <origin rpy="0 0 -0.785398163397" xyz="0 0 0" />
  </joint>
  <link name="panda2_hand">
    <inertial>
      <origin rpy="0 0 0" xyz="0 0 0.04" />
      <mass value=".81" />
      <inertia ixx="0.1" ixy="0" ixz="0" iyy="0.1" iyz="0" izz="0.1" />
    </inertial>
    <visual>
      <geometry>
        <mesh filename="package://description/meshes/visual/hand.obj" />
      </geometry>
      <material name="panda_white" />
    </visual>
    <collision>
      <geometry>
        <mesh filename="package://description/meshes/collision/hand.obj" />
      </geometry>
      <material name="panda_white" />
    </collision>
  </link>
  <link name="panda2_grasptarget">
    <inertial>
      <origin rpy="0 0 0" xyz="0 0 0" />
      <mass value="0.0" />
      <inertia ixx="0.1" ixy="0" ixz="0" iyy="0.1" iyz="0" izz="0.1" />
    </inertial>
  </link>
  <joint name="panda2_grasptarget_hand" type="fixed">
    <parent link="panda2_hand" />
    <child link="panda2_grasptarget" />
    <origin rpy="0 0 0" xyz="0 0 0.105" />
  </joint>

  <!-- all transmission -->
  <transmission name="panda2_transmission1">
    <type>transmission_interface/SimpleTransmission</type>
    <joint name="panda2_joint1">
      <hardwareInterface>hardware_interface/PositionJointInterface</hardwareInterface>
    </joint>
    <actuator name="panda2_motor1">
      <hardwareInterface>hardware_interface/PositionJointInterface</hardwareInterface>
      <mechanicalReduction>1</mechanicalReduction>
    </actuator>
  </transmission>
  <transmission name="panda2_transmission2">
    <type>transmission_interface/SimpleTransmission</type>
    <joint name="panda2_joint2">
      <hardwareInterface>hardware_interface/PositionJointInterface</hardwareInterface>
    </joint>
    <actuator name="panda2_motor2">
      <hardwareInterface>hardware_interface/PositionJointInterface</hardwareInterface>
      <mechanicalReduction>1</mechanicalReduction>
    </actuator>
  </transmission>
  <transmission name="panda2_transmission3">
    <type>transmission_interface/SimpleTransmission</type>
    <joint name="panda2_joint3">
      <hardwareInterface>hardware_interface/PositionJointInterface</hardwareInterface>
    </joint>
    <actuator name="panda2_motor3">
      <hardwareInterface>hardware_interface/PositionJointInterface</hardwareInterface>
      <mechanicalReduction>1</mechanicalReduction>
    </actuator>
  </transmission>
  <transmission name="panda2_transmission4">
    <type>transmission_interface/SimpleTransmission</type>
    <joint name="panda2_joint4">
      <hardwareInterface>hardware_interface/PositionJointInterface</hardwareInterface>
    </joint>
    <actuator name="panda2_motor4">
      <hardwareInterface>hardware_interface/PositionJointInterface</hardwareInterface>
      <mechanicalReduction>1</mechanicalReduction>
    </actuator>
  </transmission>
  <transmission name="panda2_transmission5">
    <type>transmission_interface/SimpleTransmission</type>
    <joint name="panda2_joint5">
      <hardwareInterface>hardware_interface/PositionJointInterface</hardwareInterface>
    </joint>
    <actuator name="panda2_motor5">
      <hardwareInterface>hardware_interface/PositionJointInterface</hardwareInterface>
      <mechanicalReduction>1</mechanicalReduction>
    </actuator>
  </transmission>
  <transmission name="panda2_transmission6">
    <type>transmission_interface/SimpleTransmission</type>
    <joint name="panda2_joint6">
      <hardwareInterface>hardware_interface/PositionJointInterface</hardwareInterface>
    </joint>
    <actuator name="panda2_motor6">
      <hardwareInterface>hardware_interface/PositionJointInterface</hardwareInterface>
      <mechanicalReduction>1</mechanicalReduction>
    </actuator>
  </transmission>
  <transmission name="panda2_transmission7">
    <type>transmission_interface/SimpleTransmission</type>
    <joint name="panda2_joint7">
      <hardwareInterface>hardware_interface/PositionJointInterface</hardwareInterface>
    </joint>
    <actuator name="panda2_motor7">
      <hardwareInterface>hardware_interface/PositionJointInterface</hardwareInterface>
      <mechanicalReduction>1</mechanicalReduction>
    </actuator>
  </transmission>

  <!-- all control gazebo plugin -->
  <gazebo>
    <plugin name="gazebo_ros_control" filename="libgazebo_ros_control.so">
      <robotNamespace>/panda2</robotNamespace>
      <robotSimType>gazebo_ros_control/DefaultRobotHWSim</robotSimType>
      <legacyModeNS>true</legacyModeNS>
    </plugin>
  </gazebo>

</robot>