<?xml version="1.0" encoding="utf-8"?>

<!-- =================================================================================== -->
<!-- |    This document was autogenerated by xacro from panda_arm_hand.urdf.xacro      | -->
<!-- |    EDITING THIS FILE BY HAND IS NOT RECOMMENDED                                 | -->
<!-- =================================================================================== -->
<robot name="human" xmlns:xacro="http://www.ros.org/wiki/xacro">
  <link name="world" />
  <link name="human_hand">
    <inertial>
      <origin rpy="0 0 0" xyz="0 0 0.04" />
      <mass value=".81" />
      <inertia ixx="0.1" ixy="0" ixz="0" iyy="0.1" iyz="0" izz="0.1" />
    </inertial>
    <visual>
      <geometry>
        <mesh filename="package://bringup/meshes/visual/hand.obj" />
      </geometry>
      <material name="panda_white" />
    </visual>
    <collision>
      <geometry>
        <mesh filename="package://bringup/meshes/visual/hand.obj" />
      </geometry>
      <material name="panda_white" />
    </collision>
  </link>
  <!-- TO MATCH WITH INIT POSE IN bringup.launch -->
  <joint name="human_joint_world" type="floating">
    <origin xyz="1.3 0 0.3" rpy="0 0 3.14159265" />
    <parent link="world" />
    <child link="human_hand" />
  </joint>




  <!-- all transmission -->
  <transmission name="panda2_transmission1">
    <type>transmission_interface/SimpleTransmission</type>
    <joint name="panda2_joint1">
      <hardwareInterface>hardware_interface/PositionJointInterface</hardwareInterface>
    </joint>
    <actuator name="panda2_motor1">
      <hardwareInterface>hardware_interface/PositionJointInterface</hardwareInterface>
      <mechanicalReduction>1</mechanicalReduction>
    </actuator>
  </transmission>
  <transmission name="panda2_transmission2">
    <type>transmission_interface/SimpleTransmission</type>
    <joint name="panda2_joint2">
      <hardwareInterface>hardware_interface/PositionJointInterface</hardwareInterface>
    </joint>
    <actuator name="panda2_motor2">
      <hardwareInterface>hardware_interface/PositionJointInterface</hardwareInterface>
      <mechanicalReduction>1</mechanicalReduction>
    </actuator>
  </transmission>
  <transmission name="panda2_transmission3">
    <type>transmission_interface/SimpleTransmission</type>
    <joint name="panda2_joint3">
      <hardwareInterface>hardware_interface/PositionJointInterface</hardwareInterface>
    </joint>
    <actuator name="panda2_motor3">
      <hardwareInterface>hardware_interface/PositionJointInterface</hardwareInterface>
      <mechanicalReduction>1</mechanicalReduction>
    </actuator>
  </transmission>
  <transmission name="panda2_transmission4">
    <type>transmission_interface/SimpleTransmission</type>
    <joint name="panda2_joint4">
      <hardwareInterface>hardware_interface/PositionJointInterface</hardwareInterface>
    </joint>
    <actuator name="panda2_motor4">
      <hardwareInterface>hardware_interface/PositionJointInterface</hardwareInterface>
      <mechanicalReduction>1</mechanicalReduction>
    </actuator>
  </transmission>
  <transmission name="panda2_transmission5">
    <type>transmission_interface/SimpleTransmission</type>
    <joint name="panda2_joint5">
      <hardwareInterface>hardware_interface/PositionJointInterface</hardwareInterface>
    </joint>
    <actuator name="panda2_motor5">
      <hardwareInterface>hardware_interface/PositionJointInterface</hardwareInterface>
      <mechanicalReduction>1</mechanicalReduction>
    </actuator>
  </transmission>
  <transmission name="panda2_transmission6">
    <type>transmission_interface/SimpleTransmission</type>
    <joint name="panda2_joint6">
      <hardwareInterface>hardware_interface/PositionJointInterface</hardwareInterface>
    </joint>
    <actuator name="panda2_motor6">
      <hardwareInterface>hardware_interface/PositionJointInterface</hardwareInterface>
      <mechanicalReduction>1</mechanicalReduction>
    </actuator>
  </transmission>
  <transmission name="panda2_transmission7">
    <type>transmission_interface/SimpleTransmission</type>
    <joint name="panda2_joint7">
      <hardwareInterface>hardware_interface/PositionJointInterface</hardwareInterface>
    </joint>
    <actuator name="panda2_motor7">
      <hardwareInterface>hardware_interface/PositionJointInterface</hardwareInterface>
      <mechanicalReduction>1</mechanicalReduction>
    </actuator>
  </transmission>

  <!-- all control gazebo plugin -->
  <gazebo>
    <plugin name="gazebo_ros_control" filename="libgazebo_ros_control.so">
      <robotNamespace>/panda2</robotNamespace>
      <robotSimType>gazebo_ros_control/DefaultRobotHWSim</robotSimType>
      <legacyModeNS>true</legacyModeNS>
    </plugin>
  </gazebo>

</robot>