<?xml version="1.0" encoding="utf-8"?>

<!-- =================================================================================== -->
<!-- |    This document was autogenerated by xacro from panda_arm_hand.urdf.xacro      | -->
<!-- |    EDITING THIS FILE BY HAND IS NOT RECOMMENDED                                 | -->
<!-- =================================================================================== -->
<robot name="human_hand" xmlns:xacro="http://www.ros.org/wiki/xacro">
  <link name="world" />
  <link name="human_hand">
    <inertial>
      <origin rpy="0 0 0" xyz="0 0 0.04" />
      <mass value=".81" />
      <inertia ixx="0.1" ixy="0" ixz="0" iyy="0.1" iyz="0" izz="0.1" />
    </inertial>
    <visual>
      <geometry>
        <!-- <mesh filename="package://bringup/meshes/visual/hand.obj" /> -->
        <mesh filename="package://bringup/meshes/human/hand.dae" />
      </geometry>
      <!-- <material name="panda_white" /> -->
    </visual>
    <collision>
      <geometry>
        <mesh filename="package://bringup/meshes/visual/hand.obj" />
      </geometry>
      <!-- <material name="panda_white" /> -->
    </collision>
  </link>
  <!-- TO MATCH WITH INIT POSE IN bringup.launch -->
  <joint name="human_joint_world" type="floating">
    <origin xyz="2 0.5 0.7" rpy="0 -0 3.14159" />
    <parent link="world" />
    <child link="human_hand" />
  </joint>

</robot>